Workbook

Sheet Data
A1: İŞLEM KODU | B1: BELGE TARİH | C1: BELGE NO | D1: SEVK TARİH | E1: TİP | F1: AÇIKLAMA | G1: ATOLYE KODU | H1: ORDER NO | I1: s1 | J1: s2 | K1: s3 | L1: s4 | M1: s5 | N1: s6 | O1: s7 | P1: BİRİM | Q1: KUR | R1: BİRİM FİYAT | S1: KDV | T1: Durum | U1: İŞLEM TİPİ
A2: 801 | B2: 08122022 | C2: COR2022000000450 | D2: =B2 -> 08122022 | E2: gg | F2: =C2 -> COR2022000000450 | G2: 320.10.S014 | H2: FAM0323 SS23 | I2: 0 | J2: 22 | K2: 0 | L2: 0 | M2: x | N2: x | O2: x | P2: t | Q2: 1 | R2: 92.61 | S2: 8 | T2: n | U2: P | W2: =_xlfn.XLOOKUP(H2,'Order no'!$A$3:$A$255,'Order no'!$E$3:$E$255,FALSE) -> TRUE
A3: 801 | B3: 08122022 | C3: COR2022000000450 | D3: =B3 -> 08122022 | E3: gg | F3: =C3 -> COR2022000000450 | G3: 320.10.S014 | H3: FAW0414 SS23 | I3: 0 | J3: 12 | K3: 0 | L3: 0 | M3: x | N3: x | O3: x | P3: t | Q3: 1 | R3: 90.11 | S3: 8 | T3: n | U3: P | W3: =_xlfn.XLOOKUP(H3,'Order no'!$A$3:$A$255,'Order no'!$E$3:$E$255,FALSE) -> TRUE
W4: =_xlfn.XLOOKUP(H4,'Order no'!$A$3:$A$255,'Order no'!$E$3:$E$255,FALSE) -> FALSE
W5: =_xlfn.XLOOKUP(H5,'Order no'!$A$3:$A$255,'Order no'!$E$3:$E$255,FALSE) -> FALSE
W6: =_xlfn.XLOOKUP(H6,'Order no'!$A$3:$A$255,'Order no'!$E$3:$E$255,FALSE) -> FALSE
W7: =_xlfn.XLOOKUP(H7,'Order no'!$A$3:$A$255,'Order no'!$E$3:$E$255,FALSE) -> FALSE
W8: =_xlfn.XLOOKUP(H8,'Order no'!$A$3:$A$255,'Order no'!$E$3:$E$255,FALSE) -> FALSE
W9: =_xlfn.XLOOKUP(H9,'Order no'!$A$3:$A$255,'Order no'!$E$3:$E$255,FALSE) -> FALSE
W10: =_xlfn.XLOOKUP(H10,'Order no'!$A$3:$A$255,'Order no'!$E$3:$E$255,FALSE) -> FALSE
W11: =_xlfn.XLOOKUP(H11,'Order no'!$A$3:$A$255,'Order no'!$E$3:$E$255,FALSE) -> FALSE
W12: =_xlfn.XLOOKUP(H12,'Order no'!$A$3:$A$255,'Order no'!$E$3:$E$255,FALSE) -> FALSE
W13: =_xlfn.XLOOKUP(H13,'Order no'!$A$3:$A$255,'Order no'!$E$3:$E$255,FALSE) -> FALSE
W14: =_xlfn.XLOOKUP(H14,'Order no'!$A$3:$A$255,'Order no'!$E$3:$E$255,FALSE) -> FALSE
W15: =_xlfn.XLOOKUP(H15,'Order no'!$A$3:$A$255,'Order no'!$E$3:$E$255,FALSE) -> FALSE
... W21: =_xlfn.XLOOKUP(H21,'Order no'!$A$3:$A$255,'Order no'!$E$3:$E$255,FALSE) -> FALSE

Sheet Unfinished
A1: İŞLEM KODU | B1: BELGE TARİH | C1: BELGE NO | D1: SEVK TARİH | E1: TİP | F1: AÇIKLAMA | G1: ATOLYE KODU | H1: ORDER NO | I1: Size1 | J1: Size2 | K1: Size3 | L1: Size4 | M1: Size5 | N1: Size6 | O1: Size7 | P1: BİRİM | Q1: KUR | R1: BİRİM FİYAT | S1: KDV | T1: DURUM | U1: İŞLEM TİPİ
A2: 10 | B2: 18112022 | C2: IMA2022000001994 | D2: 18112022 | E2: gg | F2: IMA2022000001994 | G2: 320.10.Y001 | H2: TAW0077 | J2: 960 | L2: x | M2: x | N2: x | O2: x | P2: t | Q2: 1 | R2: 0 | S2: 8 | T2: s | U2: U
A3: 10 | B3: 18112022 | C3: IMA2022000001994 | D3: 18112022 | E3: gg | F3: IMA2022000001994 | G3: 320.10.Y001 | H3: TAW00157 | J3: 512 | L3: x | M3: x | N3: x | O3: x | P3: t | Q3: 1 | R3: 0 | S3: 8 | T3: s | U3: U
A4: 10 | B4: 23112022 | C4: CKY2022000002325 | D4: 23112022 | E4: gg | F4: CKY2022000002325 | G4: 320.10.S014 | H4: FAM0605 SS23 DEICHMANN | J4: 4 | L4: x | M4: x | N4: x | O4: x | P4: t | Q4: 1 | R4: 0 | S4: 8 | T4: s | U4: U
A5: 10 | B5: 18112022 | C5: CKY2022000002310 | D5: 18112022 | E5: gg | F5: CKY2022000002310 | G5: 320.10.S014 | H5: FAW0411 SS23 | J5: 8 | L5: x | M5: x | N5: x | O5: x | P5: t | Q5: 1 | R5: 0 | S5: 8 | T5: s | U5: U
A6: 10 | B6: 18112022 | C6: CKY2022000002310 | D6: 18112022 | E6: gg | F6: CKY2022000002310 | G6: 320.10.S014 | H6: FAM0571 SS23 DEICHMANN | J6: 2 | L6: x | M6: x | N6: x | O6: x | P6: t | Q6: 1 | R6: 0 | S6: 8 | T6: s | U6: U
A7: 10 | B7: 21112022 | C7: CKY2022000002313 | D7: 21112022 | E7: gg | F7: CKY2022000002313 | G7: 320.10.S014 | H7: FAM0321 SS23 | J7: 425 | L7: x | M7: x | N7: x | O7: x | P7: t | Q7: 1 | R7: 0 | S7: 8 | T7: s | U7: U
A8: 10 | B8: 21112022 | C8: CKY2022000002313 | D8: 21112022 | E8: gg | F8: CKY2022000002313 | G8: 320.10.S014 | H8: FAW0444 SS23 | J8: =1629+200+414 -> 2243 | L8: x | M8: x | N8: x | O8: x | P8: t | Q8: 1 | R8: 0 | S8: 8 | T8: s | U8: U
A9: 10 | B9: 21112022 | C9: CKY2022000002313 | D9: 21112022 | E9: gg | F9: CKY2022000002313 | G9: 320.10.S014 | H9: FAM0329 SS23 | J9: =240+1468 -> 1708 | L9: x | M9: x | N9: x | O9: x | P9: t | Q9: 1 | R9: 0 | S9: 8 | T9: s | U9: U
A10: 10 | B10: 18112022 | C10: CKY2022000002275 | D10: 18112022 | E10: gg | F10: CKY2022000002275 | G10: 320.10.S014 | H10: FAW0410 SS23 | J10: 4 | L10: x | M10: x | N10: x | O10: x | P10: t | Q10: 1 | R10: 0 | S10: 8 | T10: s | U10: U
A11: 10 | B11: 18112022 | C11: CKY2022000002275 | D11: 18112022 | E11: gg | F11: CKY2022000002275 | G11: 320.10.S014 | H11: FAM0321 SS23 | J11: 33 | L11: x | M11: x | N11: x | O11: x | P11: t | Q11: 1 | R11: 0 | S11: 8 | T11: s | U11: U
A12: 10 | B12: 18112022 | C12: CKY2022000002275 | D12: 18112022 | E12: gg | F12: CKY2022000002275 | G12: 320.10.S014 | H12: FAM0579 SS23 | J12: 10 | L12: x | M12: x | N12: x | O12: x | P12: t | Q12: 1 | R12: 0 | S12: 8 | T12: s | U12: U
A13: 10 | B13: 18112022 | C13: CKY2022000002275 | D13: 18112022 | E13: gg | F13: CKY2022000002275 | G13: 320.10.S014 | H13: FAM0329 SS23 | J13: 19 | L13: x | M13: x | N13: x | O13: x | P13: t | Q13: 1 | R13: 0 | S13: 8 | T13: s | U13: U
A14: 10 | B14: 18112022 | C14: CKY2022000002275 | D14: 18112022 | E14: gg | F14: CKY2022000002275 | G14: 320.10.S014 | H14: FAW0411 SS23 | J14: 28 | L14: x | M14: x | N14: x | O14: x | P14: t | Q14: 1 | R14: 0 | S14: 8 | T14: s | U14: U
A15: 10 | B15: 18112022 | C15: CKY2022000002275 | D15: 18112022 | E15: gg | F15: CKY2022000002275 | G15: 320.10.S014 | H15: FAM0571 SS23 DEICHMANN | J15: 1 | L15: x | M15: x | N15: x | O15: x | P15: t | Q15: 1 | R15: 0 | S15: 8 | T15: s | U15: U
A16: 10 | B16: 16112022 | C16: CKY2022000002287 | D16: 16112022 | E16: gg | F16: CKY2022000002287 | G16: 320.10.S014 | H16: FAM0338 SS23 | J16: 466 | L16: x | M16: x | N16: x | O16: x | P16: t | Q16: 1 | R16: 0 | S16: 8 | T16: s | U16: U
A17: 10 | B17: 16112022 | C17: CKY2022000002287 | D17: 16112022 | E17: gg | F17: CKY2022000002287 | G17: 320.10.S014 | H17: FAM0579 SS23 | J17: 1020 | L17: x | M17: x | N17: x | O17: x | P17: t | Q17: 1 | R17: 0 | S17: 8 | T17: s | U17: U
A18: 10 | B18: 16112022 | C18: CKY2022000002287 | D18: 16112022 | E18: gg | F18: CKY2022000002287 | G18: 320.10.S014 | H18: FAM0321 SS23 | J18: 250 | L18: x | M18: x | N18: x | O18: x | P18: t | Q18: 1 | R18: 0 | S18: 8 | T18: s | U18: U
A19: 10 | B19: 16112022 | C19: CKY2022000002287 | D19: 16112022 | E19: gg | F19: CKY2022000002287 | G19: 320.10.S014 | H19: FAM0329 SS23 | J19: 229 | L19: x | M19: x | N19: x | O19: x | P19: t | Q19: 1 | R19: 0 | S19: 8 | T19: s | U19: U
A20: 801 | B20: 23112022 | C20: COR2022000000435 | D20: =B20 -> 23112022 | E20: gg | F20: =C20 -> COR2022000000435 | G20: 320.10.S014 | H20: FAM0571 SS23 DEICHMANN | I20: 0 | J20: 15 | K20: 0 | L20: 0 | M20: x | N20: x | O20: x | P20: t | Q20: 1 | R20: 64.11 | S20: 8 | T20: s | U20: P
A21: 801 | B21: 23112022 | C21: COR2022000000435 | D21: =B21 -> 23112022 | E21: gg | F21: =C21 -> COR2022000000435 | G21: 320.10.S014 | H21: FAM0565 SS23 DEICHMANN | I21: 0 | J21: 48 | K21: 0 | L21: 0 | M21: x | N21: x | O21: x | P21: t | Q21: 1 | R21: 64.11 | S21: 8 | T21: s | U21: P
A22: 801 | B22: 23112022 | C22: COR2022000000435 | D22: =B22 -> 23112022 | E22: gg | F22: =C22 -> COR2022000000435 | G22: 320.10.S014 | H22: FAM0321 SS23 | I22: 0 | J22: 108 | K22: 0 | L22: 0 | M22: x | N22: x | O22: x | P22: t | Q22: 1 | R22: 64.11 | S22: 8 | T22: 2 | U22: P
A23: 801 | B23: 23112022 | C23: COR2022000000435 | D23: =B23 -> 23112022 | E23: gg | F23: =C23 -> COR2022000000435 | G23: 320.10.S014 | H23: FAW0444 SS23 | I23: 0 | J23: 30 | K23: 0 | L23: 0 | M23: x | N23: x | O23: x | P23: t | Q23: 1 | R23: 64.11 | S23: 8 | T23: 2 | U23: P

Sheet OlderDatas
A1: İŞLEM KODU | B1: BELGE TARİH | C1: BELGE NO | D1: SEVK TARİH | E1: TİP | F1: AÇIKLAMA | G1: ATOLYE KODU | H1: ORDER NO | I1: s1 | J1: s2 | K1: s3 | L1: s4 | M1: s5 | N1: s6 | O1: s7 | P1: BİRİM | Q1: KUR | R1: BİRİM FİYAT | S1: KDV | T1: İŞLEM TİPİ
A2: 602 | B2: 28102022 | C2: GIB2022000000087 | D2: 28102022 | E2: gg | F2: GIB2022000000087 | G2: 320.10.A003 | H2: FAM0565 SS23 DEICHMANN | I2: 0 | J2: 2 | K2: 0 | L2: 0 | M2: x | N2: x | O2: x | P2: t | Q2: 1 | R2: 1000 | S2: 18 | T2: P
A3: 602 | B3: 28102022 | C3: GIB2022000000087 | D3: 28102022 | E3: gg | F3: GIB2022000000087 | G3: 320.10.A003 | H3: FAW0443 SS23 | I3: 0 | J3: 38 | K3: 0 | L3: 0 | M3: x | N3: x | O3: x | P3: t | Q3: 1 | R3: 120 | S3: 18 | T3: P
A4: 20 | B4: 04112022 | C4: IHA2022000000397 | D4: 04112022 | F4: IHA2022000000397 | G4: 120.30.Y001 | H4: FAW0685 SS23 DEICHMANN | I4: 0 | J4: 140 | K4: 0 | L4: 0 | M4: x | N4: x | O4: x | P4: e | Q4: 18.1639 | R4: 4.4 | S4: 8 | T4: U
A5: 20 | B5: 10112022 | C5: IHA2022000000401 | D5: 10112022 | F5: IHA2022000000401 | G5: 120.30.Y001 | H5: FAM0303 SS23 | I5: 0 | J5: 30 | K5: 0 | L5: 0 | M5: x | N5: x | O5: x | P5: e | Q5: 18.685 | R5: 6.3 | S5: 8 | T5: U
A6: 20 | B6: 10112022 | C6: IHA2022000000401 | D6: 10112022 | F6: IHA2022000000401 | G6: 120.30.Y001 | H6: FAM0308 SS23 | I6: 0 | J6: 22 | K6: 0 | L6: 0 | M6: x | N6: x | O6: x | P6: e | Q6: 18.685 | R6: 12.5 | S6: 8 | T6: U
A7: 20 | B7: 10112022 | C7: IHA2022000000401 | D7: 10112022 | F7: IHA2022000000401 | G7: 120.30.Y001 | H7: FAM0312 SS23 | I7: 0 | J7: 27 | K7: 0 | L7: 0 | M7: x | N7: x | O7: x | P7: e | Q7: 18.685 | R7: 7.2 | S7: 8 | T7: U
A8: 20 | B8: 10112022 | C8: IHA2022000000401 | D8: 10112022 | F8: IHA2022000000401 | G8: 120.30.Y001 | H8: FAW0382 SS23 | I8: 0 | J8: 60 | K8: 0 | L8: 0 | M8: x | N8: x | O8: x | P8: e | Q8: 18.685 | R8: 6.15 | S8: 8 | T8: U
A9: 20 | B9: 10112022 | C9: IHA2022000000401 | D9: 10112022 | F9: IHA2022000000401 | G9: 120.30.Y001 | H9: FAW0387 SS23 | I9: 0 | J9: 71 | K9: 0 | L9: 0 | M9: x | N9: x | O9: x | P9: e | Q9: 18.685 | R9: 6.05 | S9: 8 | T9: U
A10: 20 | B10: 10112022 | C10: IHA2022000000401 | D10: 10112022 | F10: IHA2022000000401 | G10: 120.30.Y001 | H10: FAW0390 SS23 | I10: 0 | J10: 50 | K10: 0 | L10: 0 | M10: x | N10: x | O10: x | P10: e | Q10: 18.685 | R10: 6.05 | S10: 8 | T10: U
A11: 20 | B11: 10112022 | C11: IHA2022000000401 | D11: 10112022 | F11: IHA2022000000401 | G11: 120.30.Y001 | H11: FAW0391 SS23 | I11: 0 | J11: 40 | K11: 0 | L11: 0 | M11: x | N11: x | O11: x | P11: e | Q11: 18.685 | R11: 7.5 | S11: 8 | T11: U
A12: 20 | B12: 10112022 | C12: IHA2022000000401 | D12: 10112022 | F12: IHA2022000000401 | G12: 120.30.Y001 | H12: FAW0396 SS23 | I12: 0 | J12: 24 | K12: 0 | L12: 0 | M12: x | N12: x | O12: x | P12: e | Q12: 18.685 | R12: 11.5 | S12: 8 | T12: U
A13: 20 | B13: 10112022 | C13: IHA2022000000401 | D13: 10112022 | F13: IHA2022000000401 | G13: 120.30.Y001 | H13: FAW0397 SS23 | I13: 0 | J13: 41 | K13: 0 | L13: 0 | M13: x | N13: x | O13: x | P13: e | Q13: 18.685 | R13: 10.8 | S13: 8 | T13: U
A14: 20 | B14: 10112022 | C14: IHA2022000000401 | D14: 10112022 | F14: IHA2022000000401 | G14: 120.30.Y001 | H14: FAW0399 SS23 | I14: 0 | J14: 41 | K14: 0 | L14: 0 | M14: x | N14: x | O14: x | P14: e | Q14: 18.685 | R14: 11.55 | S14: 8 | T14: U
A15: 20 | B15: 10112022 | C15: IHA2022000000401 | D15: 10112022 | F15: IHA2022000000401 | G15: 120.30.Y001 | H15: FAW0402 SS23 | I15: 0 | J15: 41 | K15: 0 | L15: 0 | M15: x | N15: x | O15: x | P15: e | Q15: 18.685 | R15: 9.7 | S15: 8 | T15: U
A16: 20 | B16: 10112022 | C16: IHA2022000000401 | D16: 10112022 | F16: IHA2022000000401 | G16: 120.30.Y001 | H16: FAW0417 SS23 | I16: 0 | J16: 73 | K16: 0 | L16: 0 | M16: x | N16: x | O16: x | P16: e | Q16: 18.685 | R16: 7.45 | S16: 8 | T16: U
... A26: 20 | B26: 10112022 | C26: IHA2022000000400 | D26: 10112022 | F26: IHA2022000000400 | G26: 120.30.Y001 | H26: FAW0396 SS23 | I26: 0 | J26: 20 | K26: 0 | L26: 0 | M26: x | N26: x | O26: x | P26: e | Q26: 18.685 | R26: 11.5 | S26: 8 | T26: U
A27: 20 | B27: 04112022 | C27: IHA2022000000397 | D27: 04112022 | F27: IHA2022000000397 | G27: 320.30.Y001 | H27: FAW0685 SS23 DEICHMANN | I27: 0 | J27: 140 | K27: 0 | L27: 0 | M27: x | N27: x | O27: x | P27: e | Q27: 18.1639 | R27: 4.4 | S27: 8 | T27: U
A28: 20 | B28: 10112022 | C28: IHA2022000000401 | D28: 10112022 | F28: IHA2022000000401 | G28: 320.30.Y001 | H28: FAM0303 SS23 | I28: 0 | J28: 30 | K28: 0 | L28: 0 | M28: x | N28: x | O28: x | P28: e | Q28: 18.685 | R28: 6.3 | S28: 8 | T28: U
A29: 20 | B29: 10112022 | C29: IHA2022000000401 | D29: 10112022 | F29: IHA2022000000401 | G29: 320.30.Y001 | H29: FAM0308 SS23 | I29: 0 | J29: 22 | K29: 0 | L29: 0 | M29: x | N29: x | O29: x | P29: e | Q29: 18.685 | R29: 12.5 | S29: 8 | T29: U
A30: 20 | B30: 10112022 | C30: IHA2022000000401 | D30: 10112022 | F30: IHA2022000000401 | G30: 320.30.Y001 | H30: FAM0312 SS23 | I30: 0 | J30: 27 | K30: 0 | L30: 0 | M30: x | N30: x | O30: x | P30: e | Q30: 18.685 | R30: 7.2 | S30: 8 | T30: U
A31: 20 | B31: 10112022 | C31: IHA2022000000401 | D31: 10112022 | F31: IHA2022000000401 | G31: 320.30.Y001 | H31: FAW0382 SS23 | I31: 0 | J31: 60 | K31: 0 | L31: 0 | M31: x | N31: x | O31: x | P31: e | Q31: 18.685 | R31: 6.15 | S31: 8 | T31: U
A32: 20 | B32: 10112022 | C32: IHA2022000000401 | D32: 10112022 | F32: IHA2022000000401 | G32: 320.30.Y001 | H32: FAW0387 SS23 | I32: 0 | J32: 71 | K32: 0 | L32: 0 | M32: x | N32: x | O32: x | P32: e | Q32: 18.685 | R32: 6.05 | S32: 8 | T32: U
A33: 20 | B33: 10112022 | C33: IHA2022000000401 | D33: 10112022 | F33: IHA2022000000401 | G33: 320.30.Y001 | H33: FAW0390 SS23 | I33: 0 | J33: 50 | K33: 0 | L33: 0 | M33: x | N33: x | O33: x | P33: e | Q33: 18.685 | R33: 6.05 | S33: 8 | T33: U
A34: 20 | B34: 10112022 | C34: IHA2022000000401 | D34: 10112022 | F34: IHA2022000000401 | G34: 320.30.Y001 | H34: FAW0391 SS23 | I34: 0 | J34: 40 | K34: 0 | L34: 0 | M34: x | N34: x | O34: x | P34: e | Q34: 18.685 | R34: 7.5 | S34: 8 | T34: U
A35: 20 | B35: 10112022 | C35: IHA2022000000401 | D35: 10112022 | F35: IHA2022000000401 | G35: 320.30.Y001 | H35: FAW0396 SS23 | I35: 0 | J35: 24 | K35: 0 | L35: 0 | M35: x | N35: x | O35: x | P35: e | Q35: 18.685 | R35: 11.5 | S35: 8 | T35: U
A36: 20 | B36: 10112022 | C36: IHA2022000000401 | D36: 10112022 | F36: IHA2022000000401 | G36: 320.30.Y001 | H36: FAW0397 SS23 | I36: 0 | J36: 41 | K36: 0 | L36: 0 | M36: x | N36: x | O36: x | P36: e | Q36: 18.685 | R36: 10.8 | S36: 8 | T36: U
A37: 20 | B37: 10112022 | C37: IHA2022000000401 | D37: 10112022 | F37: IHA2022000000401 | G37: 320.30.Y001 | H37: FAW0399 SS23 | I37: 0 | J37: 41 | K37: 0 | L37: 0 | M37: x | N37: x | O37: x | P37: e | Q37: 18.685 | R37: 11.55 | S37: 8 | T37: U
A38: 20 | B38: 10112022 | C38: IHA2022000000401 | D38: 10112022 | F38: IHA2022000000401 | G38: 320.30.Y001 | H38: FAW0402 SS23 | I38: 0 | J38: 41 | K38: 0 | L38: 0 | M38: x | N38: x | O38: x | P38: e | Q38: 18.685 | R38: 9.7 | S38: 8 | T38: U
A39: 20 | B39: 10112022 | C39: IHA2022000000401 | D39: 10112022 | F39: IHA2022000000401 | G39: 320.30.Y001 | H39: FAW0417 SS23 | I39: 0 | J39: 73 | K39: 0 | L39: 0 | M39: x | N39: x | O39: x | P39: e | Q39: 18.685 | R39: 7.45 | S39: 8 | T39: U
... A49: 20 | B49: 10112022 | C49: IHA2022000000400 | D49: 10112022 | F49: IHA2022000000400 | G49: 320.30.Y001 | H49: FAW0396 SS23 | I49: 0 | J49: 20 | K49: 0 | L49: 0 | M49: x | N49: x | O49: x | P49: e | Q49: 18.685 | R49: 11.5 | S49: 8 | T49: U
A50: 20 | B50: 18112022 | C50: IHA2022000000404 | D50: 18112022 | F50: IHA2022000000404 | G50: 320.30.Y001 | H50: FAM0303 SS23 | I50: 0 | J50: 193 | K50: 0 | L50: x | M50: x | N50: x | O50: x | P50: e | Q50: 19.2822 | R50: 6.3 | S50: 8 | T50: U
A51: 20 | B51: 18112022 | C51: IHA2022000000404 | D51: 18112022 | F51: IHA2022000000404 | G51: 320.30.Y001 | H51: FAM0308 SS23 | I51: 0 | J51: 926 | K51: 0 | L51: x | M51: x | N51: x | O51: x | P51: e | Q51: 19.2822 | R51: 12.5 | S51: 8 | T51: U
A52: 20 | B52: 18112022 | C52: IHA2022000000404 | D52: 18112022 | F52: IHA2022000000404 | G52: 320.30.Y001 | H52: FAM0303 SS23 | I52: 0 | J52: 389 | K52: 0 | L52: x | M52: x | N52: x | O52: x | P52: e | Q52: 19.2822 | R52: 7.2 | S52: 8 | T52: U
A53: 800 | B53: 18112022 | C53: IMA2022000001994 | D53: 18112022 | E53: gg | F53: IMA2022000001994 | G53: 320.10.Y001 | H53: TAW0077 | I53: 0 | J53: 960 | K53: 0 | L53: x | M53: x | N53: x | O53: x | P53: t | Q53: 1 | R53: 6 | S53: 8 | T53: P
A54: 800 | B54: 18112022 | C54: IMA2022000001994 | D54: 18112022 | E54: gg | F54: IMA2022000001994 | G54: 320.10.Y001 | H54: TAW0157 | I54: 0 | J54: 512 | K54: 0 | L54: x | M54: x | N54: x | O54: x | P54: t | Q54: 1 | R54: 6 | S54: 8 | T54: P
A55: 801 | B55: 23112022 | C55: CKY2022000002325 | D55: 23112022 | E55: gg | F55: CKY2022000002325 | G55: 320.10.S014 | H55: FAM0605 SS23 DEICHMANN | I55: 0 | J55: 4 | K55: 0 | L55: x | M55: x | N55: x | O55: x | P55: t | Q55: 1 | R55: 120.11 | S55: 8 | T55: P
A56: 801 | B56: 18112022 | C56: CKY2022000002310 | D56: 18112022 | E56: gg | F56: CKY2022000002310 | G56: 320.10.S014 | H56: FAW0411 SS23 | I56: 0 | J56: 8 | K56: 0 | L56: x | M56: x | N56: x | O56: x | P56: t | Q56: 1 | R56: 68.61 | S56: 8 | T56: P
A57: 801 | B57: 18112022 | C57: CKY2022000002310 | D57: 18112022 | E57: gg | F57: CKY2022000002310 | G57: 320.10.S014 | H57: FAM0571 SS23 DEICHMANN | I57: 0 | J57: 2 | K57: 0 | L57: x | M57: x | N57: x | O57: x | P57: t | Q57: 1 | R57: 64.11 | S57: 8 | T57: P
A58: 801 | B58: 21112022 | C58: CKY2022000002313 | D58: 21112022 | E58: gg | F58: CKY2022000002313 | G58: 320.10.S014 | H58: FAM0321 SS23 | I58: 0 | J58: =1629+200+414 -> 2243 | K58: 0 | L58: x | M58: x | N58: x | O58: x | P58: t | Q58: 1 | R58: 68.61 | S58: 8 | T58: P
...

Sheet Not
A1: İşlem Kodu: Parça işçilik için 800-801 gibi sayılar // Üretim Analiz için 10-Üretim, 20-Ticari Mal
A2: Tip: Bu kısım parça işçilik faturasının Giden/Gelen bilgisi içindir. g: giden // gg: Gelen
A3: Birim: t:TL // e:EUR // u:USD // g:GBP
A4: Kur: Farklı bir kur varsa kullanılır.
A5: İşlem Tipi: U: Üretim Analiz // P: Parça İşçilik

Sheet Kodlar
B2: Siba | C2: 320.10.S014 | F2: Baskı | G2: 150
B3: Maz Fason | C3: 320.10.M002 | F3: Ütü Paket | G3: 800
B4: Ali Alıcı | C4: 320.10.A003
B5: YFA EUR | C5: 320.30.Y001
B6: YFA TRY | C6: 320.10.Y001

Sheet Order no
A2: Order No | B2: Model No | C2: Model Adı | D2: Order Adedi
A3: FAM0303 | B3: FAM0303 | C3: CASTELLAR oversized tee | D3: 52 | E3: TRUE
A4: FAM0307 | B4: FAM0307 | C4: CUENCA kimono hoodie | D4: 52 | E4: TRUE
A5: FAM0308 | B5: FAM0308 | C5: CUENCA oversized hoody | D5: 52 | E5: TRUE
A6: FAM0312 | B6: FAM0312 | C6: CALP baggy shorts | D6: 52 | E6: TRUE
A7: FAM0314 | B7: FAM0314 | C7: CHIPUDE oversized pants | D7: 52 | E7: TRUE
A8: FAM0316 | B8: FAM0316 | C8: CORRALEJO jacket | D8: 52 | E8: TRUE
A9: FAM0320 | B9: FAM0320 | C9: BILECIK raglan crew sweat | D9: 100 | E9: TRUE
A10: FAM0321 | B10: FAM0321 | C10: BISCEGLIE hoody | D10: 56 | E10: TRUE
A11: FAM0322 | B11: FAM0322 | C11: BOYABAT shorts | D11: 100 | E11: TRUE
A12: FAM0323 | B12: FAM0323 | C12: BOTTROP track jacket | D12: 52 | E12: TRUE
A13: FAM0324 | B13: FAM0324 | C13: BOTTROP track pants | D13: 52 | E13: TRUE
A14: FAM0326 | B14: FAM0326 | C14: BLANKAHOLM hoody | D14: 52 | E14: TRUE
... A255: TF-FA-01 | B255: TF-FA-01 | C255: TexFortis Soccer Jersey | D255: 1095 | E255: TRUE

Sheet Stocker
